<?xml version="1.0"?>
<robot xmlns:xacro="http://www.ros.org/wiki/xacro">
  <xacro:macro name="qube">
    <!--Base Cube-->
    <link name="base_link">
      <visual>
        <geometry><box size="1.02 1.02 1.02"/></geometry>
        <material name="black"><color rgba="0.1 0.1 0.1 1"/></material>
      </visual>
      <collision><geometry><box size="0.001 0.001 0.001"/></geometry></collision>
      <inertial>
        <mass value="0.5"/>
        <inertia ixx="0.100" ixy="0" ixz="0" iyy="0.100" iyz="0" izz="0.100"/>
      </inertial>
    </link>

    <!--Spinning Top-->
    <link name="spinning_disk">
      <visual>
        <geometry><cylinder radius="0.25" length="0.1"/></geometry>
        <origin xyz="0 0 0.26" rpy="0 0 0"/> 
        <material name="red"><color rgba="1 0 0 1"/></material>
      </visual>
      <collision>
        <geometry><cylinder radius="0.025" length="0.01"/></geometry>
        <origin xyz="0 0 0.26" rpy="0 0 0"/>
      </collision>
      <inertial>
        <mass value="0.1"/>
        <inertia ixx="0.1000" ixy="0" ixz="0" iyy="0.1000" iyz="0" izz="0.1000"/>
      </inertial>
    </link>

    <!--Revolute Joint-->
    <joint name="motor_joint" type="revolute">
      <parent link="base_link"/>
      <child link="spinning_disk"/>
      <axis xyz="0 0 -1"/>  <!--Inverted to make the simulation and actual system move the same way-->
      <origin xyz="0 0 0.26"/>
      <limit effort="100" velocity="100" lower="-314000000" upper="314000000"/>
    </joint>

    <joint name="indicator_joint" type="fixed">
      <parent link="spinning_disk"/>
      <child link="indicator_link"/>
      <origin xyz="0.125 0 0.31"/>
    </joint>
    <!--Indicator-->
    <link name="indicator_link">
      <visual>
        <geometry>
          <box size="0.25 0.02 0.02"/>
        </geometry>
        <material name="indicator_white">
          <color rgba="1 1 1 1"/>
        </material>
      </visual>
    </link>
  </xacro:macro>
</robot>